Workbook

Sheet Cashflow_Misa
B1: 2026 - BẢNG THEO DÕI DÒNG TIỀN
D2: % | E2: TỔNG | F2: Jan | H2: Feb | J2: March | L2: April | N2: May | P2: June | R2: July | T2: August | V2: September | X2: October | Z2: November | AB2: December | AD2: %
B3: ĐẦU KỲ | I3: =G66 -> 10000 | K3: =I66 -> 10000 | M3: =K66 -> 10000 | O3: =M66 -> 10000 | Q3: =O66 -> 10000 | S3: =Q66 -> 10000 | U3: =S66 -> 10000 | W3: =U66 -> 10000 | X3: =V66 -> #DIV/0! | Y3: =W66 -> 10000 | AA3: =Y66 -> 10000 | AC3: =AA66 -> 10000
B4: LÃI/LỖ | E4: =G4+I4+K4+M4+O4+Q4+S4+U4+W4+Y4+AA4+AC4 -> 0 | G4: =G5-G16 -> 0 | H4: =H5-H16 -> 0 | I4: =I5-I16 -> 0 | J4: =J5-J16 -> 0 | K4: =K5-K16 -> 0 | L4: =L5-L16 -> 0 | M4: =M5-M16 -> 0 | N4: =N5-N16 -> 0 | ... U4: =U5-U16 -> 0 | W4: =W5-W16 -> 0 | Y4: =Y5-Y16 -> 0 | AA4: =AA5-AA16 -> 0 | AC4: =AC5-AC16 -> 0
B5: THU | D5: =E4/E5 -> #DIV/0! | E5: =G5+I5+K5+M5+O5+Q5+S5+U5+W5+Y5+AA5+AC5 -> 0 | G5: =SUBTOTAL(9,G6:G15)-G13 -> 0 | I5: =SUBTOTAL(9,I6:I15)-I13 -> 0 | K5: =SUBTOTAL(9,K6:K15)-K13 -> 0 | M5: =SUBTOTAL(9,M6:M15)-M13 -> 0 | O5: =SUBTOTAL(9,O6:O15)-O13 -> 0 | Q5: =SUBTOTAL(9,Q6:Q15)-Q13 -> 0 | S5: =SUBTOTAL(9,S6:S15)-S13 -> 0 | U5: =SUBTOTAL(9,U6:U15)-U13 -> 0 | W5: =SUBTOTAL(9,W6:W15)-W13 -> 0 | Y5: =SUBTOTAL(9,Y6:Y15)-Y13 -> 0 | AA5: =SUBTOTAL(9,AA6:AA15)-AA13 -> 0 | AC5: =SUBTOTAL(9,AC6:AC15)-AC13 -> 0
B6: Thu dự án | D6: =E6+E14+E11 -> 0 | E6: =G6+I6+K6+M6+O6+Q6+S6+U6+W6+Y6+AA6+AC6 -> 0 | F6: 521 | G6: =SUBTOTAL(9,$G$7:$G$9) -> 0 | H6: =I6/$I$5 -> #DIV/0! | I6: =SUBTOTAL(9,I7:I9) -> 0 | J6: =K6/$K$5 -> #DIV/0! | K6: =SUBTOTAL(9,K7:K9) -> 0 | L6: =M6/$M$5 -> #DIV/0! | M6: =SUBTOTAL(9,M7:M9) -> 0 | N6: =O6/$O$5 -> #DIV/0! | O6: =SUBTOTAL(9,O7:O9) -> 0 | P6: =Q6/$Q$5 -> #DIV/0! | Q6: =SUBTOTAL(9,Q7:Q9) -> 0 | R6: =S6/$S$5 -> #DIV/0! | S6: =SUBTOTAL(9,S7:S9) -> 0 | T6: =U6/$U$5 -> #DIV/0! | U6: =SUBTOTAL(9,U7:U9) -> 0 | W6: =SUBTOTAL(9,W7:W9) -> 0 | X6: =SUBTOTAL(9,X7:X9) -> 0 | Y6: =SUBTOTAL(9,Y7:Y9) -> 0 | Z6: =SUBTOTAL(9,Z7:Z9) -> 0 | AA6: =SUBTOTAL(9,AA7:AA9) -> 0 | AB6: =SUBTOTAL(9,AB7:AB9) -> 0 | AC6: =SUBTOTAL(9,AC7:AC9) -> 0 | AD6: =E6/$E$5 -> #DIV/0!
A7: 131+515.1-635.1 | C7: --T&M | D7: =E5-D6 -> 0 | E7: =G7+I7+K7+M7+O7+Q7+S7+U7+W7+Y7+AA7+AC7 -> 0 | AD7: =E7/$E$5 -> #DIV/0!
C8: -- Fixed Price | E8: =G8+I8+K8+M8+O8+Q8+S8+U8+W8+Y8+AA8+AC8 -> 0 | AD8: =E8/$E$5 -> #DIV/0!
C9: --Doanh thu từ môi giới, giới thiệu | D9: =D7-D6 -> 0 | E9: =G9+I9+K9+M9+O9+Q9+S9+U9+W9+Y9+AA9+AC9 -> 0 | F9: 0 | AD9: =E9/$E$5 -> #DIV/0!
B10: Thu đầu tư tài chính, tiết kiệm | E10: =G10+I10+K10+M10+O10+Q10+S10+U10+W10+Y10+AA10+AC10 -> 0 | AD10: =E10/$E$5 -> #DIV/0!
B11: Thu đầu tư R&D | E11: =G11+I11+K11+M11+O11+Q11+S11+U11+W11+Y11+AA11+AC11 -> 0 | AD11: =E11/$E$5 -> #DIV/0!
A12: 515.2+711.2 | B12: Thu khác | C12: Thu hoàn lương, cp gửi xe chi hộ, hoàn mua hộ cho KH, hoàn tiền chi hộ cho ds đính kèm hoạt động NB | E12: =G12+I12+K12+M12+O12+Q12+S12+U12+W12+Y12+AA12+AC12 -> 0 | F12: 9350 | AD12: =E12/$E$5 -> #DIV/0!
A13: 711.1 | B13: Thu từ khấu trừ thuế CTV | C13: =E14+E15 -> 0 | E13: =G13+I13+K13+M13+O13+Q13+S13+U13+W13+Y13+AA13+AC13 -> 0 | F13: 0 | AD13: =E13/$E$5 -> #DIV/0!
A14: 515.1-635.1 | B14: Lãi/lỗ TG | C14: Lãi/lỗ TG thanh toán | E14: =G14+I14+K14+M14+O14+Q14+S14+U14+W14+Y14+AA14+AC14 -> 0 | F14: 0 | AD14: =E14/$E$5 -> #DIV/0!
A15: 515.4-635.2 | C15: Lãi/lỗ TG rút tiền | E15: =G15+I15+K15+M15+O15+Q15+S15+U15+W15+Y15+AA15+AC15 -> 0 | AD15: =E15/$E$5 -> #DIV/0!
B16: CHI | E16: =G16+I16+K16+M16+O16+Q16+S16+U16+W16+Y16+AA16+AC16 -> 0 | G16: =SUBTOTAL(9,G17:G65) -> 0 | H16: =SUBTOTAL(9,H17:H65) -> 0 | I16: =SUBTOTAL(9,I17:I65) -> 0 | J16: =SUBTOTAL(9,J17:J65) -> 0 | K16: =SUBTOTAL(9,K17:K65) -> 0 | L16: =SUBTOTAL(9,L17:L65) -> 0 | M16: =SUBTOTAL(9,M17:M65) -> 0 | N16: =SUBTOTAL(9,N17:N65) -> 0 | ... AC16: =SUBTOTAL(9,AC17:AC65) -> 0
B17: Lương dự án | D17: =E17/$E$5 -> #DIV/0! | E17: =G17+I17+K17+M17+O17+Q17+S17+U17+W17+Y17+AA17+AC17 -> 0 | F17: -50928 | G17: =SUBTOTAL(9,G18:G22) -> 0 | H17: =SUBTOTAL(9,H18:H22) -> 0 | I17: =SUBTOTAL(9,I18:I22) -> 0 | J17: =SUBTOTAL(9,J18:J22) -> 0 | K17: =SUBTOTAL(9,K18:K22) -> 0 | L17: =SUBTOTAL(9,L18:L22) -> 0 | M17: =SUBTOTAL(9,M18:M22) -> 0 | N17: =SUBTOTAL(9,N18:N22) -> 0 | ... U17: =SUBTOTAL(9,U18:U22) -> 0 | V17: =W17/$W$6 -> #DIV/0! | W17: =SUBTOTAL(9,W18:W22) -> 0 | X17: =SUBTOTAL(9,X18:X22) -> 0 | Y17: =SUBTOTAL(9,Y18:Y22) -> 0 | Z17: =AA17/$AA$6 -> #DIV/0! | AA17: =SUBTOTAL(9,AA18:AA22) -> 0 | AB17: =SUBTOTAL(9,AB18:AB22) -> 0 | AC17: =SUBTOTAL(9,AC18:AC22) -> 0 | AD17: =E17/$E$5 -> #DIV/0!
C18: Lương nhân viên nội bộ | D18: =E18/$E$5 -> #DIV/0! | E18: =G18+I18+K18+M18+O18+Q18+S18+U18+W18+Y18+AA18+AC18 -> 0 | AD18: =E18/$E$5 -> #DIV/0!
C19: Lương nhân viên thuê ngoài trực tiếp (freelancer) | D19: =E19/$E$5 -> #DIV/0! | E19: =G19+I19+K19+M19+O19+Q19+S19+U19+W19+Y19+AA19+AC19 -> 0 | AD19: =E19/$E$5 -> #DIV/0!
C20: Lương nhân viên thuê nhà cung cấp (vendor) | D20: =E20/$E$5 -> #DIV/0! | E20: =G20+I20+K20+M20+O20+Q20+S20+U20+W20+Y20+AA20+AC20 -> 0 | AD20: =E20/$E$5 -> #DIV/0!
C21: Chi phí đầu tư đào tạo nhân lực (cử đi đào tạo, học tiếng anh...) | D21: =E21/$E$5 -> #DIV/0! | E21: =G21+I21+K21+M21+O21+Q21+S21+U21+W21+Y21+AA21+AC21 -> 0 | F21: 0 | AD21: =E21/$E$5 -> #DIV/0!
C22: Chi phí công tác, công cụ, sự kiện dành cho team dự án | D22: =E22/$E$5 -> #DIV/0! | E22: =G22+I22+K22+M22+O22+Q22+S22+U22+W22+Y22+AA22+AC22 -> 0 | AD22: =E22/$E$5 -> #DIV/0!
B23: Quản lý văn phòng | D23: =E23/$E$5 -> #DIV/0! | E23: =G23+I23+K23+M23+O23+Q23+S23+U23+W23+Y23+AA23+AC23 -> 0 | F23: -591650 | G23: =SUBTOTAL(9,G24:G26) -> 0 | H23: =SUBTOTAL(9,H24:H26) -> 0 | I23: =SUBTOTAL(9,I24:I26) -> 0 | J23: =SUBTOTAL(9,J24:J26) -> 0 | K23: =SUBTOTAL(9,K24:K27) -> 0 | L23: =SUBTOTAL(9,L24:L26) -> 0 | M23: =SUBTOTAL(9,M24:M26) -> 0 | N23: =SUBTOTAL(9,N24:N26) -> 0 | O23: =SUBTOTAL(9,O24:O27) -> 0 | P23: =SUBTOTAL(9,P24:P27) -> 0 | Q23: =SUBTOTAL(9,Q24:Q27) -> 0 | R23: =SUBTOTAL(9,R24:R27) -> 0 | S23: =SUBTOTAL(9,S24:S27) -> 0 | T23: =SUBTOTAL(9,T24:T26) -> 0 | U23: =SUBTOTAL(9,U24:U26) -> 0 | V23: =W23/$W$6 -> #DIV/0! | W23: =SUBTOTAL(9,W24:W26) -> 0 | X23: =SUBTOTAL(9,X24:X26) -> 0 | Y23: =SUBTOTAL(9,Y24:Y26) -> 0 | Z23: =AA23/$AA$6 -> #DIV/0! | AA23: =SUBTOTAL(9,AA24:AA26) -> 0 | AB23: =SUBTOTAL(9,AB24:AB26) -> 0 | AC23: =SUBTOTAL(9,AC24:AC26) -> 0 | AD23: =E23/$E$5 -> #DIV/0!
A24: chia theo pbo | C24: Chi phí thuê nhà | D24: =E24/$E$5 -> #DIV/0! | E24: =G24+I24+K24+M24+O24+Q24+S24+U24+W24+Y24+AA24+AC24 -> 0 | AD24: =E24/$E$5 -> #DIV/0!
C25: Dịch vụ/Điện/Nước/Gửi xe... | D25: =E25/$E$5 -> #DIV/0! | E25: =G25+I25+K25+M25+O25+Q25+S25+U25+W25+Y25+AA25+AC25 -> 0 | AD25: =E25/$E$5 -> #DIV/0!
C26: Chi phí mua sắm, phục vụ văn phòng cơ bản | D26: =E26/$E$5 -> #DIV/0! | E26: =G26+I26+K26+M26+O26+Q26+S26+U26+W26+Y26+AA26+AC26 -> 0 | AD26: =E26/$E$5 -> #DIV/0!
C27: Chi phí đầu tư Singapore | D27: =E27/$E$5 -> #DIV/0! | E27: =G27+I27+K27+M27+O27+Q27+S27+U27+W27+Y27+AA27+AC27 -> 0 | AD27: =E27/$E$5 -> #DIV/0!
B28: Chi phí đảm bảo chất lượng | D28: =E28/$E$5 -> #DIV/0! | E28: =G28+I28+K28+M28+O28+Q28+S28+U28+W28+Y28+AA28+AC28 -> 0 | F28: -1548 | G28: =SUBTOTAL(9,G29:G30) -> 0 | H28: =SUBTOTAL(9,H29:H30) -> 0 | I28: =SUBTOTAL(9,I29:I30) -> 0 | J28: =SUBTOTAL(9,J29:J30) -> 0 | K28: =SUBTOTAL(9,K29:K30) -> 0 | L28: =SUBTOTAL(9,L29:L30) -> 0 | M28: =SUBTOTAL(9,M29:M30) -> 0 | N28: =SUBTOTAL(9,N29:N30) -> 0 | ... U28: =SUBTOTAL(9,U29:U30) -> 0 | V28: =W28/$W$6 -> #DIV/0! | W28: =SUBTOTAL(9,W29:W30) -> 0 | X28: =SUBTOTAL(9,X29:X30) -> 0 | Y28: =SUBTOTAL(9,Y29:Y30) -> 0 | Z28: =AA28/$AA$6 -> #DIV/0! | AA28: =SUBTOTAL(9,AA29:AA30) -> 0 | AB28: =SUBTOTAL(9,AB29:AB30) -> 0 | AC28: =SUBTOTAL(9,AC29:AC30) -> 0 | AD28: =E28/$E$5 -> #DIV/0!
C29: ISO | D29: =E29/$E$6 -> #DIV/0! | E29: =G29+I29+K29+M29+O29+Q29+S29+U29+W29+Y29+AA29+AC29 -> 0 | AD29: =E29/$E$5 -> #DIV/0!
C30: Chi phí quản lý | D30: =E30/$E$6 -> #DIV/0! | E30: =G30+I30+K30+M30+O30+Q30+S30+U30+W30+Y30+AA30+AC30 -> 0 | AD30: =E30/$E$5 -> #DIV/0!
B31: Hành chính/ Nhân Sự | D31: =E31/$E$5 -> #DIV/0! | E31: =G31+I31+K31+M31+O31+Q31+S31+U31+W31+Y31+AA31+AC31 -> 0 | G31: =SUBTOTAL(9,G32:G33) -> 0 | H31: =SUBTOTAL(9,H32:H33) -> 0 | I31: =SUBTOTAL(9,I32:I33) -> 0 | J31: =SUBTOTAL(9,J32:J33) -> 0 | K31: =SUBTOTAL(9,K32:K33) -> 0 | L31: =SUBTOTAL(9,L32:L33) -> 0 | M31: =SUBTOTAL(9,M32:M33) -> 0 | N31: =SUBTOTAL(9,N32:N33) -> 0 | ... U31: =SUBTOTAL(9,U32:U33) -> 0 | V31: =W31/$W$6 -> #DIV/0! | W31: =SUBTOTAL(9,W32:W33) -> 0 | X31: =SUBTOTAL(9,X32:X33) -> 0 | Y31: =SUBTOTAL(9,Y32:Y33) -> 0 | Z31: =AA31/$AA$6 -> #DIV/0! | AA31: =SUBTOTAL(9,AA32:AA33) -> 0 | AB31: =SUBTOTAL(9,AB32:AB33) -> 0 | AC31: =SUBTOTAL(9,AC32:AC33) -> 0 | AD31: =E31/$E$5 -> #DIV/0!
A32: 6421.2 | C32: Lương/Thưởng cho bộ phận HCNS | D32: =E32/$E$6 -> #DIV/0! | E32: =G32+I32+K32+M32+O32+Q32+S32+U32+W32+Y32+AA32+AC32 -> 0 | AD32: =E32/$E$5 -> #DIV/0!
C33: Các chi phí hoạt động nội bộ | D33: =E33/$E$6 -> #DIV/0! | E33: =G33+I33+K33+M33+O33+Q33+S33+U33+W33+Y33+AA33+AC33 -> 0 | AD33: =E33/$E$5 -> #DIV/0!
B34: Kế toán/Tài Chính | D34: =E34/$E$5-0.3% -> #DIV/0! | E34: =G34+I34+K34+M34+O34+Q34+S34+U34+W34+Y34+AA34+AC34 -> 0 | G34: =SUBTOTAL(9,G35:G36) -> 0 | H34: =SUBTOTAL(9,H35:H36) -> 0 | I34: =SUBTOTAL(9,I35:I36) -> 0 | J34: =SUBTOTAL(9,J35:J36) -> 0 | K34: =SUBTOTAL(9,K35:K36) -> 0 | L34: =SUBTOTAL(9,L35:L36) -> 0 | M34: =SUBTOTAL(9,M35:M36) -> 0 | N34: =SUBTOTAL(9,N35:N36) -> 0 | ... U34: =SUBTOTAL(9,U35:U36) -> 0 | V34: =W34/$W$6 -> #DIV/0! | W34: =SUBTOTAL(9,W35:W36) -> 0 | X34: =SUBTOTAL(9,X35:X36) -> 0 | Y34: =SUBTOTAL(9,Y35:Y36) -> 0 | Z34: =AA34/$AA$6 -> #DIV/0! | AA34: =SUBTOTAL(9,AA35:AA36) -> 0 | AB34: =SUBTOTAL(9,AB35:AB36) -> 0 | AC34: =SUBTOTAL(9,AC35:AC36) -> 0 | AD34: =E34/$E$5 -> #DIV/0!
A35: 6422.6 | C35: Lương bộ phận kế toán | D35: =E35/$E$5-0.3% -> #DIV/0! | E35: =G35+I35+K35+M35+O35+Q35+S35+U35+W35+Y35+AA35+AC35 -> 0 | AD35: =E35/$E$5 -> #DIV/0!
C36: Chi phí xử lý thuế, các vấn đề về kế toán (nếu có) | D36: =E36/$E$5 -> #DIV/0! | E36: =G36+I36+K36+M36+O36+Q36+S36+U36+W36+Y36+AA36+AC36 -> 0 | AD36: =E36/$E$5 -> #DIV/0!
B37: Sales | D37: =E37/$E$5 -> #DIV/0! | E37: =G37+I37+K37+M37+O37+Q37+S37+U37+W37+Y37+AA37+AC37 -> 0 | F37: -5558 | G37: =SUBTOTAL(9,G38:G43) -> 0 | H37: =SUBTOTAL(9,H38:H43) -> 0 | I37: =SUBTOTAL(9,I38:I43) -> 0 | J37: =SUBTOTAL(9,J38:J43) -> 0 | K37: =SUBTOTAL(9,K38:K43) -> 0 | L37: =SUBTOTAL(9,L38:L43) -> 0 | M37: =SUBTOTAL(9,M38:M43) -> 0 | N37: =SUBTOTAL(9,N38:N43) -> 0 | ... U37: =SUBTOTAL(9,U38:U43) -> 0 | V37: =W37/$W$6 -> #DIV/0! | W37: =SUBTOTAL(9,W38:W43) -> 0 | X37: =SUBTOTAL(9,X38:X43) -> 0 | Y37: =SUBTOTAL(9,Y38:Y43) -> 0 | Z37: =AA37/$AA$6 -> #DIV/0! | AA37: =SUBTOTAL(9,AA38:AA43) -> 0 | AB37: =SUBTOTAL(9,AB38:AB43) -> 0 | AC37: =SUBTOTAL(9,AC38:AC43) -> 0 | AD37: =E37/$E$5 -> #DIV/0!
A38: 6421.3 | C38: Lương NV Sales | D38: =E38/$E$5 -> #DIV/0! | E38: =G38+I38+K38+M38+O38+Q38+S38+U38+W38+Y38+AA38+AC38 -> 0 | AD38: =E38/$E$5 -> #DIV/0!
A39: 6421.4 | C39: Công cụ phục vụ Sales | D39: =E39/$E$5 -> #DIV/0! | E39: =G39+I39+K39+M39+O39+Q39+S39+U39+W39+Y39+AA39+AC39 -> 0 | AD39: =E39/$E$5 -> #DIV/0!
A40: 6421.5 | C40: Tiếp khách | D40: =E40/$E$5 -> #DIV/0! | E40: =G40+I40+K40+M40+O40+Q40+S40+U40+W40+Y40+AA40+AC40 -> 0 | AD40: =E40/$E$5 -> #DIV/0!
...

Sheet Bản sao của Cashflow_Misa 1
B1: 2025 - BẢNG THEO DÕI DÒNG TIỀN
B3: Chú giải: | G3: Text | I3: Text | K3: : Số liệu đã update thực tế, đã xảy ra
I4: Text | K4: : Số liệu planned
D6: % | E6: TỔNG | F6: Jan | H6: Feb | J6: March | L6: April | N6: May | P6: June | R6: July | T6: August | V6: September | X6: October | Z6: November | AB6: December | AD6: % | AF6: FINANCIAL INDEX
B7: ĐẦU KỲ | I7: =G69 -> 0 | K7: =I69 -> 0 | M7: =K69 -> 0 | O7: =M69 -> 0 | Q7: =O69 -> 0 | S7: =Q69 -> 0 | U7: =S69 -> 0 | W7: =U69 -> 0 | X7: =V69 -> 0 | Y7: =W69 -> 0 | AA7: =Y69 -> 0 | AC7: =AA69 -> 0 | AF7: Avg. 2M Expense | AG7: =E20/2 -> 0
B8: LÃI/LỖ | E8: =G8+I8+K8+M8+O8+Q8+S8+U8+W8+Y8+AA8+AC8 -> 0 | G8: =G9-G20 -> 0 | H8: =H9-H20 -> 0 | I8: =I9-I20 -> 0 | J8: =J9-J20 -> 0 | K8: =K9-K20 -> 0 | L8: =L9-L20 -> 0 | M8: =M9-M20 -> 0 | N8: =N9-N20 -> 0 | ... U8: =U9-U20 -> 0 | W8: =W9-W20 -> 0 | Y8: =Y9-Y20 -> 0 | AA8: =AA9-AA20 -> 0 | AC8: =AC9-AC20 -> 0 | AF8: OVERDRAFT | AG8: =2096000000+1000000000+100000000 -> 3196000000
B9: THU | E9: =G9+I9+K9+M9+O9+Q9+S9+U9+W9+Y9+AA9+AC9 -> 0 | G9: =SUBTOTAL(9,G10:G19)-G17 -> 0 | I9: =SUBTOTAL(9,I10:I19)-I17 -> 0 | K9: =SUBTOTAL(9,K10:K19)-K17 -> 0 | M9: =SUBTOTAL(9,M10:M19)-M17 -> 0 | O9: =SUBTOTAL(9,O10:O19)-O17 -> 0 | Q9: =SUBTOTAL(9,Q10:Q19)-Q17 -> 0 | S9: =SUBTOTAL(9,S10:S19)-S17 -> 0 | U9: =SUBTOTAL(9,U10:U19)-U17 -> 0 | W9: =SUBTOTAL(9,W10:W19)-W17 -> 0 | Y9: =SUBTOTAL(9,Y10:Y19)-Y17 -> 0 | AA9: =SUBTOTAL(9,AA10:AA19)-AA17 -> 0 | AC9: =SUBTOTAL(9,AC10:AC19)-AC17 -> 0 | AF9: Loan | AG9: 200000000
B10: Thu dự án | AD10: =E10/$E$9 -> #DIV/0! | AF10: ET. Current Ratio | AG10: =(I69+AG8+AG9)/AG7 -> #DIV/0!
A11: 131+515.1-635.1 | C11: --T&M | AD11: =E11/$E$9 -> #DIV/0! | AF11: ROS in Jan | AG11: =AG15/AG13 -> #DIV/0!
C12: -- Fixed Price | AD12: =E12/$E$9 -> #DIV/0! | AF12: ROS in 2025 | AG12: =AG18/AG16 -> #DIV/0!
C13: --Doanh thu từ môi giới, giới thiệu | AD13: =E13/$E$9 -> #DIV/0! | AF13: Total Income Feb | AG13: =I9 -> 0
B14: Thu đầu tư tài chính, tiết kiệm | AD14: =E14/$E$9 -> #DIV/0! | AF14: Total Expense Feb | AG14: =I20 -> 0
B15: Thu đầu tư R&D | AD15: =E15/$E$9 -> #DIV/0! | AF15: Net Earning Feb | AG15: =AG13-AG14 -> 0
A16: 515.2+711.2 | B16: Thu khác | C16: Thu hoàn lương, cp gửi xe chi hộ, hoàn mua hộ cho KH, hoàn tiền chi hộ cho ds đính kèm hoạt động NB | AD16: =E16/$E$9 -> #DIV/0! | AF16: Total Income 2025 | AG16: =E9 -> 0
A17: 711.1 | B17: Thu từ khấu trừ thuế CTV | AD17: =E17/$E$9 -> #DIV/0! | AF17: Total Expense 2025 | AG17: =E20 -> 0
A18: 515.1-635.1 | B18: Lãi/lỗ TG | C18: Lãi/lỗ TG thanh toán | AD18: =E18/$E$9 -> #DIV/0! | AF18: Net Earning 2025 | AG18: =AG16-AG17 -> 0
A19: 515.4-635.2 | C19: Lãi/lỗ TG rút tiền | AD19: =E19/$E$9 -> #DIV/0!
B20: CHI
B21: Lương dự án | AD21: =E21/$E$9 -> #DIV/0!
B22: 334.1 | C22: Lương nhân viên nội bộ | AD22: =E22/$E$9 -> #DIV/0!
B23: 334.2 | C23: Lương nhân viên thuê ngoài trực tiếp (freelancer) | AD23: =E23/$E$9 -> #DIV/0!
B24: 331 | C24: Lương nhân viên thuê nhà cung cấp (vendor) | AD24: =E24/$E$9 -> #DIV/0!
B25: 6421-17 | C25: Chi phí đầu tư đào tạo nhân lực (cử đi đào tạo, học tiếng anh...) | AD25: =E25/$E$9 -> #DIV/0!
B26: 154 | C26: Chi phí công tác, công cụ, sự kiện dành cho team dự án | AD26: =E26/$E$9 -> #DIV/0!
B27: Quản lý văn phòng | AD27: =E27/$E$9 -> #DIV/0!
A28: chia theo pbo | B28: 242 | C28: Chi phí thuê nhà | AD28: =E28/$E$9 -> #DIV/0!
B29: 6422.2 | C29: Dịch vụ/Điện/Nước/Gửi xe... | AD29: =E29/$E$9 -> #DIV/0!
B30: 6422.3 | C30: Chi phí mua sắm, phục vụ văn phòng cơ bản | AD30: =E30/$E$9 -> #DIV/0!
B31: Chi phí đảm bảo chất lượng | AD31: =E31/$E$9 -> #DIV/0!
B32: 6421.1 | C32: ISO | AD32: =E32/$E$9 -> #DIV/0!
B33: 6422.4 | C33: Chi phí quản lý | AD33: =E33/$E$9 -> #DIV/0!
B34: Hành chính/ Nhân Sự | AD34: =E34/$E$9 -> #DIV/0!
A35: 6421.2 | B35: 334.5 | C35: Lương/Thưởng cho bộ phận HCNS | AD35: =E35/$E$9 -> #DIV/0!
B36: 6422.5 | C36: Các chi phí hoạt động nội bộ | AD36: =E36/$E$9 -> #DIV/0!
B37: Kế toán/Tài Chính | AD37: =E37/$E$9 -> #DIV/0!
A38: 6422.6 | B38: 334.3 | C38: Lương bộ phận kế toán | AD38: =E38/$E$9 -> #DIV/0!
B39: 6422.7 | C39: Chi phí xử lý thuế, các vấn đề về kế toán (nếu có) | AD39: =E39/$E$9 -> #DIV/0!
B40: Sales | AD40: =E40/$E$9 -> #DIV/0! | AE40: =8/100*E10 -> 0 | AF40: =AE40-E40-E47 -> 0
A41: 6421.3 | B41: 334.6 | C41: Lương NV Sales | AD41: =E41/$E$9 -> #DIV/0!
A42: 6421.4 | C42: Công cụ phục vụ Sales | AD42: =E42/$E$9 -> #DIV/0!
...

Sheet Bản sao của Cashflow_Misa
B1: 2024 - BẢNG THEO DÕI DÒNG TIỀN
B3: Chú giải: | G3: Text | I3: Text | K3: : Số liệu đã update thực tế, đã xảy ra
I4: Text | K4: : Số liệu planned
D6: % | E6: TỔNG | F6: Jan | H6: Feb | J6: March | L6: April | N6: May | P6: June | R6: July | T6: August | V6: September | X6: October | Z6: November | AB6: December | AD6: % | AF6: FINANCIAL INDEX
B7: ĐẦU KỲ | G7: 2686639687 | I7: =G68 -> 4239048626 | K7: =I68 -> 3522316950 | M7: =K68 -> 3772272859 | O7: =M68 -> 3911889608 | Q7: =O68 -> 3973634228 | S7: =Q68 -> 4822733262 | U7: =S68 -> 5058911628 | W7: =U68 -> 4785275712 | X7: =V68 -> 0 | Y7: =W68 -> 4952988949 | AA7: =Y68 -> 5256312713 | AC7: =AA68 -> 5463955565 | AF7: Avg. 11M Expense | AG7: =E19/11 -> 2.0502953e+09
B8: LÃI/LỖ | E8: =G8+I8+K8+M8+O8+Q8+S8+U8+W8+Y8+AA8+AC8 -> 1157095616 | G8: =G9-G19 -> 1552408939 | H8: =H9-H19 -> 0 | I8: =I9-I19 -> -716731676 | J8: =J9-J19 -> 0 | K8: =K9-K19 -> 249955909 | L8: =L9-L19 -> 0 | M8: =M9-M19 -> 139616749 | N8: =N9-N19 -> 0 | ... U8: =U9-U19 -> -273635916 | W8: =W9-W19 -> 167713237 | Y8: =Y9-Y19 -> 303323764 | AA8: =AA9-AA19 -> 207642852 | AC8: =AC9-AC19 -> -1620220262 | AF8: OVERDRAFT | AG8: =2096000000+1000000000+100000000 -> 3196000000
B9: THU | E9: =G9+I9+K9+M9+O9+Q9+S9+U9+W9+Y9+AA9+AC9 -> 23710343643 | G9: =SUBTOTAL(9,G10:G18)-G16 -> 3274924980 | I9: =SUBTOTAL(9,I10:I18)-I16 -> 1646972576 | K9: =SUBTOTAL(9,K10:K18)-K16 -> 1809790827 | M9: =SUBTOTAL(9,M10:M18)-M16 -> 1830212715 | O9: =SUBTOTAL(9,O10:O18)-O16 -> 1923384218 | Q9: =SUBTOTAL(9,Q10:Q18)-Q16 -> 2348702879 | S9: =SUBTOTAL(9,S10:S18)-S16 -> 1937537786 | U9: =SUBTOTAL(9,U10:U18)-U16 -> 1888078435 | W9: =SUBTOTAL(9,W10:W18)-W16 -> 1879611092 | Y9: =SUBTOTAL(9,Y10:Y18)-Y16 -> 2555920718 | AA9: =SUBTOTAL(9,AA10:AA18)-AA16 -> 2516690542 | AC9: =SUBTOTAL(9,AC10:AC18)-AC16 -> 98516875 | AF9: Loan | AG9: 200000000
B10: Thu dự án | E10: =G10+I10+K10+M10+O10+Q10+S10+U10+W10+Y10+AA10+AC10 -> 22415957275 | F10: =G10/$G$9 -> 0.68189884 | G10: =SUBTOTAL(9,$G$11:$G$13) -> 2233167559 | H10: =I10/$I$9 -> 0.98321479 | I10: =SUBTOTAL(9,I11:I13) -> 1619327800 | J10: =K10/$K$9 -> 0.97515353 | K10: =SUBTOTAL(9,K11:K13) -> 1764823908 | L10: =M10/$M$9 -> 0.98556087 | M10: =SUBTOTAL(9,M11:M13) -> 1803786037 | N10: =O10/$O$9 -> 0.97745496 | O10: =SUBTOTAL(9,O11:O13) -> 1880021436 | P10: =Q10/$Q$9 -> 0.99158313 | Q10: =SUBTOTAL(9,Q11:Q13) -> 2328934149 | R10: =S10/$S$9 -> 0.98113774 | S10: =SUBTOTAL(9,S11:S13) -> 1900991447 | T10: =U10/$U$9 -> 1.0239262 | U10: =SUBTOTAL(9,U11:U13) -> 1933252957 | W10: =SUBTOTAL(9,W11:W13) -> 1858161375 | X10: =SUBTOTAL(9,X11:X13) -> 1 | Y10: =SUBTOTAL(9,Y11:Y13) -> 2537335754 | Z10: =SUBTOTAL(9,Z11:Z13) -> 1 | AA10: =SUBTOTAL(9,AA11:AA13) -> 2462282592 | AB10: =SUBTOTAL(9,AB11:AB13) -> 0 | AC10: =SUBTOTAL(9,AC11:AC13) -> 93872261 | AD10: =E10/$E$9 -> 0.94540837 | AF10: ET. Current Ratio | AG10: =(Q68+AG8)/AG7 -> 3.9110139
A11: 131+515.1-635.1 | C11: --T&M | E11: =G11+I11+K11+M11+O11+Q11+S11+U11+W11+Y11+AA11+AC11 -> 19723937155 | F11: 0.9353 | G11: 2088667559 | H11: 1 | I11: 1619327800 | J11: 0.9188 | K11: 1621543108 | L11: 0.9077 | M11: 1661209237 | N11: 0.8508 | O11: 1636406123 | P11: 0.7989 | Q11: 1876345517 | R11: 0.8613 | S11: 1668879138 | T11: =U11/$U$9 -> 0.96547217 | U11: 1822887188 | V11: =W11/$W$10 -> 0.90535682 | W11: 1682299075 | X11: =Y11/$Y$10 -> 0.7480725 | Y11: =1943349196 -45238095 -> 1898111101 | Z11: =AA11/$AA$10 -> 0.8548097 | AA11: 2104783048 | AC11: 43478261 | AD11: =E11/$E$9 -> 0.83187057 | AF11: ROS in Nov | AG11: =AG15/AG13 -> 0.082506311
C12: -- Fixed Price | E12: =G12+I12+K12+M12+O12+Q12+S12+U12+W12+Y12+AA12+AC12 -> 2692020120 | F12: 0.0647 | G12: 144500000 | H12: 0 | I12: 0 | J12: 0.0812 | K12: 143280800 | L12: 0.0779 | M12: 142576800 | N12: 0.1267 | O12: 243615313 | P12: 0.1927 | Q12: 452588632 | R12: 0.1198 | S12: 232112309 | T12: =U12/$U$9 -> 0.058454017 | U12: 110365769 | V12: =W12/$W$10 -> 0.094643179 | W12: 175862300 | X12: =Y12/$Y$10 -> 0.2519275 | Y12: =639469253-244600 -> 639224653 | Z12: =AA12/$AA$10 -> 0.1451903 | AA12: 357499544 | AC12: 50394000 | AD12: =E12/$E$9 -> 0.11353779 | AF12: ROS in 2024 | AG12: =AG18/AG16 -> 0.048801301
C13: --Doanh thu từ môi giới, giới thiệu | E13: =G13+I13+K13+M13+O13+Q13+S13+U13+W13+Y13+AA13+AC13 -> 0 | F13: 0 | G13: 0 | H13: 0 | I13: 0 | J13: 0 | K13: 0 | L13: 0 | M13: 0 | N13: 0 | O13: 0 | P13: 0 | Q13: 0 | R13: 0 | S13: 0 | T13: =U13/$U$9 -> 0 | U13: 0 | V13: =W13/$W$10 -> 0 | X13: =Y13/$Y$10 -> 0 | Z13: =AA13/$AA$10 -> 0 | AD13: =E13/$E$9 -> 0 | AF13: Total Income Nov | AG13: =AA9 -> 2516690542
B14: Thu đầu tư tài chính, tiết kiệm | E14: =G14+I14+K14+M14+O14+Q14+S14+U14+W14+Y14+AA14+AC14 -> 1042679674 | F14: 0.4595 | G14: 1026096751 | H14: 0 | I14: 0 | J14: 0 | K14: 0 | L14: 0.0001 | M14: 138136 | N14: 0 | O14: 0 | P14: 0 | Q14: 0 | R14: 0 | S14: 0 | T14: =U14/$U$9 -> 0 | U14: 0 | V14: =W14/$W$10 -> 0 | X14: =Y14/$Y$10 -> 0 | Z14: =AA14/$AA$10 -> 0.0066786757 | AA14: 16444787 | AD14: =E14/$E$9 -> 0.04397573 | AF14: Total Expense Nov | AG14: =AA19 -> 2309047690
A15: 515.2+711.2 | B15: Thu khác | C15: Thu hoàn lương, cp gửi xe chi hộ, hoàn mua hộ cho KH, hoàn tiền chi hộ cho ds đính kèm hoạt động NB | E15: =G15+I15+K15+M15+O15+Q15+S15+U15+W15+Y15+AA15+AC15 -> 203096291 | F15: 0.0048 | G15: 10675690 | H15: 0.0123 | I15: 19923176 | J15: 0.0116 | K15: 20451705 | L15: 0.0065 | M15: 11895702 | N15: 0.0189 | O15: 36410212 | P15: 0.0084 | Q15: 19768730 | R15: 0.0149 | S15: 28848049 | T15: =U15/$U$9 -> 0.00057146937 | U15: =76179+1002800 -> 1078979 | V15: =W15/$W$10 -> 0.017616062 | W15: =56286+32677200 -> 32733486 | X15: =Y15/$Y$10 -> 0.0027824887 | Y15: =41188+7018920 -> 7060108 | Z15: =AA15/$AA$10 -> 0.005373077 | AA15: =32853+13197181 -> 13230034 | AC15: 1020420 | AD15: =E15/$E$9 -> 0.0085657253 | AF15: Net Earning Nov | AG15: =AG13-AG14 -> 207642852
A16: 711.1 | B16: Thu từ khấu trừ thuế CTV | E16: =G16+I16+K16+M16+O16+Q16+S16+U16+W16+Y16+AA16+AC16 -> 15800000 | F16: 0 | G16: 0 | H16: 0 | I16: 0 | J16: 0 | K16: 0 | L16: 0 | M16: 0 | N16: 0 | O16: 0 | P16: 0 | Q16: 0 | R16: 0 | S16: 0 | T16: =U16/$U$9 -> 0.0012181697 | U16: 2300000 | V16: =W16/$W$10 -> 0.0011839661 | W16: 2200000 | X16: =Y16/$Y$10 -> 0.0027193878 | Y16: 6900000 | Z16: =AA16/$AA$10 -> 0.00093409262 | AA16: 2300000 | AC16: 2100000 | AD16: =E16/$E$9 -> 0.00066637583 | AF16: Total Income 2024 | AG16: =E9 -> 23710343643
A17: 515.1-635.1 | B17: Lãi/lỗ TG | C17: Lãi/lỗ TG thanh toán | E17: =G17+I17+K17+M17+O17+Q17+S17+U17+W17+Y17+AA17+AC17 -> 379596 | F17: 0 | G17: 0 | H17: 0 | I17: 0 | J17: 0 | K17: 0 | L17: 0 | M17: 0 | N17: 0 | O17: 0 | P17: 0 | Q17: 0 | R17: 0 | S17: 0 | T17: =U17/$U$9 -> -0.0052347317 | U17: =770240-10653824 -> -9883584 | V17: =W17/$W$10 -> -0.0060725452 | W17: -11283769 | X17: =Y17/$Y$10 -> 0.0059511935 | Y17: =28656582 -13556406 -> 15100176 | Z17: =AA17/$AA$10 -> 0.0026157733 | AA17: =6559263-118490 -> 6440773 | AC17: 6000 | AD17: =E17/$E$9 -> 1.6009722e-05 | AF17: Total Expense 2024 | AG17: =E19 -> 22553248027
A18: 515.4-635.2 | C18: Lãi/lỗ TG rút tiền | E18: =G18+I18+K18+M18+O18+Q18+S18+U18+W18+Y18+AA18+AC18 -> 48230807 | G18: 4984980 | I18: 7721600 | K18: 24515214 | M18: 14392840 | N18: 0 | O18: 6952570 | P18: 0 | Q18: 0 | R18: 0.004 | S18: 7698290 | T18: =U18/$U$9 -> -0.019262927 | U18: -36369917 | V18: =W18/$W$10 -> 0 | W18: 0 | X18: =Y18/$Y$10 -> -0.0014090843 | Y18: -3575320 | Z18: =AA18/$AA$10 -> 0.0074290238 | AA18: =18499720-207364 -> 18292356 | AC18: =5965041-2346847 -> 3618194 | AD18: =E18/$E$9 -> 0.0020341674 | AF18: Net Earning 2024 | AG18: =AG16-AG17 -> 1157095616
B19: CHI | E19: =G19+I19+K19+M19+O19+Q19+S19+U19+W19+Y19+AA19+AC19 -> 22553248027 | G19: =SUBTOTAL(9,G20:G67) -> 1722516041 | I19: =SUBTOTAL(9,I20:I67) -> 2363704252 | K19: =SUBTOTAL(9,K20:K67) -> 1559834918 | M19: =SUBTOTAL(9,M20:M67) -> 1690595966 | O19: =SUBTOTAL(9,O20:O67) -> 1861639598 | Q19: =SUBTOTAL(9,Q20:Q67) -> 1499603845 | S19: =SUBTOTAL(9,S20:S67) -> 1701359420 | U19: =SUBTOTAL(9,U20:U67) -> 2161714351 | W19: =SUBTOTAL(9,W20:W67) -> 1711897855 | X19: =SUBTOTAL(9,X20:X67) -> 0.8877804 | Y19: =SUBTOTAL(9,Y20:Y67) -> 2252596954 | AA19: =SUBTOTAL(9,AA20:AA67) -> 2309047690 | AC19: =SUBTOTAL(9,AC20:AC67) -> 1718737137
B20: Lương dự án | D20: =E20/$E$10 -> 0.53894405 | E20: =G20+I20+K20+M20+O20+Q20+S20+U20+W20+Y20+AA20+AC20 -> 12080946836 | F20: 0.4572 | G20: =SUBTOTAL(9,G21:G25) -> 1020907859 | H20: =SUBTOTAL(9,H21:H25) -> 0.5814 | I20: =SUBTOTAL(9,I21:I25) -> 941315262 | J20: =SUBTOTAL(9,J21:J25) -> 0.4645 | K20: =SUBTOTAL(9,K21:K25) -> 819692583 | L20: =SUBTOTAL(9,L21:L25) -> 0.4697 | M20: =SUBTOTAL(9,M21:M25) -> 859451950 | N20: =SUBTOTAL(9,N21:N25) -> 0.4673 | ... U20: =SUBTOTAL(9,U21:U25) -> 1047255037 | V20: =W20/$W$10 -> 0.52737567 | W20: =SUBTOTAL(9,W21:W25) -> 979949099 | X20: =SUBTOTAL(9,X21:X25) -> 0.4626142 | Y20: =SUBTOTAL(9,Y21:Y25) -> 1173807557 | Z20: =AA20/$AA$10 -> 0.48473517 | AA20: =SUBTOTAL(9,AA21:AA25) -> 1193554971 | AB20: =SUBTOTAL(9,AB21:AB25) -> 0 | AC20: =SUBTOTAL(9,AC21:AC25) -> 1228326323 | AD20: =E20/$E$9 -> 0.50952222
B21: 334.1 | C21: Lương nhân viên nội bộ | D21: =E21/$E$10 -> 0.24440532 | E21: =G21+I21+K21+M21+O21+Q21+S21+U21+W21+Y21+AA21+AC21 -> 5478579104 | F21: 0.1787 | G21: 399102045 | H21: 0.2125 | I21: 344041300 | J21: 0.2085 | K21: 367916299 | L21: 0.2311 | M21: 422918183 | N21: 0.2301 | O21: 442561022 | P21: 0.1887 | Q21: 443212265 | R21: 0.2602 | S21: 504052512 | T21: =U21/$U$9 -> 0.27323221 | U21: 515883846 | V21: =W21/$W$10 -> 0.27863768 | W21: 517753781 | X21: =Y21/$Y$10 -> 0.20392936 | Y21: 517437257 | Z21: =AA21/$AA$10 -> 0.20873539 | AA21: 513965519 | AC21: 489735075 | AD21: =E21/$E$9 -> 0.23106283
B22: 334.2 | C22: Lương nhân viên thuê ngoài trực tiếp (freelancer) | D22: =E22/$E$10 -> 0.12773717 | E22: =G22+I22+K22+M22+O22+Q22+S22+U22+W22+Y22+AA22+AC22 -> 2863350893 | F22: 0.1273 | G22: 284173664 | H22: 0.1846 | I22: 298908567 | J22: 0.1015 | K22: 179163970 | L22: 0.097 | M22: 177453906 | N22: 0.0931 | O22: 179162272 | P22: 0.0738 | Q22: 173300259 | R22: 0.1238 | S22: 239798988 | T22: =U22/$U$9 -> 0.1050325 | U22: 198309593 | V22: =W22/$W$10 -> 0.1085338 | W22: 201673318 | X22: =Y22/$Y$10 -> 0.12127313 | Y22: 307710648 | Z22: =AA22/$AA$10 -> 0.13972669 | AA22: 344046603 | AC22: =12000000+267649105 -> 279649105 | AD22: =E22/$E$9 -> 0.12076379
B23: 331 | C23: Lương nhân viên thuê nhà cung cấp (vendor) | D23: =E23/$E$10 -> 0.15826511 | E23: =G23+I23+K23+M23+O23+Q23+S23+U23+W23+Y23+AA23+AC23 -> 3547664035 | F23: 0.1392 | G23: 310918810 | H23: 0.1748 | I23: 282992152 | J23: 0.1175 | K23: 207310304 | L23: 0.1416 | M23: 259079861 | N23: 0.132 | O23: 253971632 | P23: 0.1276 | Q23: 299704745 | R23: 0.1326 | S23: 256829500 | T23: =U23/$U$9 -> 0.16227949 | U23: 306396398 | V23: =W23/$W$10 -> 0.14020418 | W23: 260522000 | X23: =Y23/$Y$10 -> 0.1299401 | Y23: =374939747-45238095 -> 329701652 | Z23: =AA23/$AA$10 -> 0.13584625 | AA23: 334491849 | AC23: =50000000+395745132 -> 445745132 | AD23: =E23/$E$9 -> 0.14962516
B24: 6421-17 | C24: Chi phí đầu tư đào tạo nhân lực (cử đi đào tạo, học tiếng anh...) | D24: =E24/$E$10 -> 0.0014852366 | E24: =G24+I24+K24+M24+O24+Q24+S24+U24+W24+Y24+AA24+AC24 -> 33293000 | F24: 0 | G24: 0 | H24: 0.0062 | I24: 10000000 | J24: 0 | K24: 0 | L24: 0 | M24: 0 | N24: 0.0121 | O24: 23293000 | P24: 0 | Q24: 0 | R24: 0 | S24: 0 | T24: =U24/$U$9 -> 0 | U24: 0 | V24: =W24/$W$10 -> 0 | X24: =Y24/$Y$10 -> 0 | Z24: =AA24/$AA$10 -> 0 | AD24: =E24/$E$9 -> 0.0014041551
B25: 154 | C25: Chi phí công tác, công cụ, sự kiện dành cho team dự án | D25: =E25/$E$10 -> 0.0070512181 | E25: =G25+I25+K25+M25+O25+Q25+S25+U25+W25+Y25+AA25+AC25 -> 158059804 | F25: 0.012 | G25: 26713340 | H25: 0.0033 | I25: 5373243 | J25: 0.037 | K25: 65302010 | L25: 0 | M25: 0 | N25: 0 | O25: 0 | P25: 0 | Q25: 0 | R25: 0.0004 | S25: 800000 | T25: =U25/$U$9 -> 0.01412293 | U25: 26665200 | V25: =W25/$W$10 -> 0 | X25: =Y25/$Y$10 -> 0.0074716166 | Y25: 18958000 | Z25: =AA25/$AA$10 -> 0.00042683972 | AA25: 1051000 | AC25: 13197011 | AD25: =E25/$E$9 -> 0.0066662806
B26: Quản lý văn phòng | D26: =E26/$E$10 -> 0.065909906 | E26: =G26+I26+K26+M26+O26+Q26+S26+U26+W26+Y26+AA26+AC26 -> 1477433628 | F26: 0.0065 | G26: =SUBTOTAL(9,G27:G29) -> 14525138 | H26: =SUBTOTAL(9,H27:H29) -> 0.1741 | I26: =SUBTOTAL(9,I27:I29) -> 281992770 | J26: =SUBTOTAL(9,J27:J29) -> 0.0205 | K26: =SUBTOTAL(9,K27:K29) -> 36173939 | L26: =SUBTOTAL(9,L27:L29) -> 0.0131 | M26: =SUBTOTAL(9,M27:M29) -> 23917338 | N26: =SUBTOTAL(9,N27:N29) -> 0.1593 | ... U26: =SUBTOTAL(9,U27:U29) -> 329763716 | V26: =W26/$W$10 -> 0.011157151 | W26: =SUBTOTAL(9,W27:W29) -> 20731787 | X26: =SUBTOTAL(9,X27:X29) -> 0.027105189 | Y26: =SUBTOTAL(9,Y27:Y29) -> 68774964 | Z26: =AA26/$AA$10 -> 0.1276686 | AA26: =SUBTOTAL(9,AA27:AA29) -> 314356168 | AB26: =SUBTOTAL(9,AB27:AB29) -> 0 | AC26: =SUBTOTAL(9,AC27:AC29) -> 22771335 | AD26: =E26/$E$9 -> 0.062311776
A27: chia theo pbo | B27: 242 | C27: Chi phí thuê nhà | D27: =E27/$E$10 -> 0.050957538 | E27: =G27+I27+K27+M27+O27+Q27+S27+U27+W27+Y27+AA27+AC27 -> 1142262000 | F27: 0 | G27: 0 | H27: 0.1664 | I27: 269505600 | J27: 0.006 | K27: 10560000 | L27: 0 | M27: 0 | N27: 0.1447 | O27: 278230680 | P27: 0 | Q27: 0 | R27: 0 | S27: 0 | T27: =U27/$U$9 -> 0.15646861 | U27: 295425000 | V27: =W27/$W$10 -> 0 | X27: =Y27/$Y$10 -> 0 | Z27: =AA27/$AA$10 -> 0.11718424 | AA27: 288540720 | AD27: =E27/$E$9 -> 0.048175683
B28: 6422.2 | C28: Dịch vụ/Điện/Nước/Gửi xe... | D28: =E28/$E$10 -> 0.01024912 | E28: =G28+I28+K28+M28+O28+Q28+S28+U28+W28+Y28+AA28+AC28 -> 229743836 | F28: 0.006 | G28: 13452448 | H28: 0.0073 | I28: 11852360 | J28: 0.0072 | K28: 12704505 | L28: 0.0095 | M28: 17377870 | N28: 0.0109 | O28: 21000714 | P28: 0.0099 | Q28: 23204393 | R28: 0.0115 | S28: 22245946 | T28: =U28/$U$9 -> 0.012098649 | U28: 22843199 | V28: =W28/$W$10 -> 0.011013417 | W28: 20464707 | X28: =Y28/$Y$10 -> 0.008350479 | Y28: 21187969 | Z28: =AA28/$AA$10 -> 0.0084107832 | AA28: 20709725 | AC28: =1700000+21000000 -> 22700000 | AD28: =E28/$E$9 -> 0.0096896038
B29: 6422.3 | C29: Chi phí mua sắm, phục vụ văn phòng cơ bản | D29: =E29/$E$10 -> 0.0047032474 | E29: =G29+I29+K29+M29+O29+Q29+S29+U29+W29+Y29+AA29+AC29 -> 105427792 | F29: 0.0005 | G29: 1072690 | H29: 0.0004 | I29: 634810 | J29: 0.0073 | K29: 12909434 | L29: 0.0036 | M29: 6539468 | N29: 0.0037 | O29: 7085360 | P29: 0.0007 | Q29: 1554580 | R29: 0.0057 | S29: 11104800 | T29: =U29/$U$9 -> 0.0060884743 | U29: 11495517 | V29: =W29/$W$10 -> 0.00014373348 | W29: 267080 | X29: =Y29/$Y$10 -> 0.01875471 | Y29: =45720000+1866995 -> 47586995 | Z29: =AA29/$AA$10 -> 0.0020735731 | AA29: 5105723 | AC29: 71335 | AD29: =E29/$E$9 -> 0.0044464894
B30: Chi phí đảm bảo chất lượng | D30: =E30/$E$10 -> 0.0022376024 | E30: =G30+I30+K30+M30+O30+Q30+S30+U30+W30+Y30+AA30+AC30 -> 50158000 | F30: 0.0027 | G30: =SUBTOTAL(9,G31:G32) -> 6000000 | H30: =SUBTOTAL(9,H31:H32) -> 0.0037 | I30: =SUBTOTAL(9,I31:I32) -> 6000000 | J30: =SUBTOTAL(9,J31:J32) -> 0.0181 | K30: =SUBTOTAL(9,K31:K32) -> 31900000 | L30: =SUBTOTAL(9,L31:L32) -> 0 | M30: =SUBTOTAL(9,M31:M32) -> 0 | N30: =SUBTOTAL(9,N31:N32) -> 0 | ... U30: =SUBTOTAL(9,U31:U32) -> 6000000 | V30: =W30/$W$10 -> 0 | W30: =SUBTOTAL(9,W31:W32) -> 0 | X30: =SUBTOTAL(9,X31:X32) -> 0 | Y30: =SUBTOTAL(9,Y31:Y32) -> 0 | Z30: =AA30/$AA$10 -> 0 | AA30: =SUBTOTAL(9,AA31:AA32) -> 0 | AB30: =SUBTOTAL(9,AB31:AB32) -> 0 | AC30: =SUBTOTAL(9,AC31:AC32) -> 0 | AD30: =E30/$E$9 -> 0.002115448
B31: 6421.1 | C31: ISO | D31: =E31/$E$10 -> 0.00053533293 | E31: =G31+I31+K31+M31+O31+Q31+S31+U31+W31+Y31+AA31+AC31 -> 12000000 | F31: 0.0027 | G31: 6000000 | H31: 0.0037 | I31: 6000000 | J31: 0 | K31: 0 | L31: 0 | M31: 0 | N31: 0 | O31: 0 | P31: 0 | Q31: 0 | R31: 0 | S31: 0 | T31: =U31/$U$9 -> 0 | U31: 0 | V31: =W31/$W$10 -> 0 | X31: =Y31/$Y$10 -> 0 | Z31: =AA31/$AA$10 -> 0 | AD31: =E31/$E$9 -> 0.00050610823
B32: 6422.4 | C32: Chi phí quản lý | D32: =E32/$E$10 -> 0.0017022695 | E32: =G32+I32+K32+M32+O32+Q32+S32+U32+W32+Y32+AA32+AC32 -> 38158000 | F32: 0 | G32: 0 | H32: 0 | I32: 0 | J32: 0.0181 | K32: 31900000 | L32: 0 | M32: 0 | N32: 0 | O32: 0 | P32: 0.0001 | Q32: 258000 | R32: 0 | S32: 0 | T32: =U32/$U$9 -> 0.0031778341 | U32: 6000000 | V32: =W32/$W$10 -> 0 | X32: =Y32/$Y$10 -> 0 | Z32: =AA32/$AA$10 -> 0 | AD32: =E32/$E$9 -> 0.0016093398
B33: Hành chính/ Nhân Sự | D33: =E33/$E$10 -> 0.043375899 | E33: =G33+I33+K33+M33+O33+Q33+S33+U33+W33+Y33+AA33+AC33 -> 972312294 | F33: 0.0192 | G33: =SUBTOTAL(9,G34:G35) -> 42881806 | H33: =SUBTOTAL(9,H34:H35) -> 0.0278 | I33: =SUBTOTAL(9,I34:I35) -> 44977675 | J33: =SUBTOTAL(9,J34:J35) -> 0.0322 | K33: =SUBTOTAL(9,K34:K35) -> 56896750 | L33: =SUBTOTAL(9,L34:L35) -> 0.0318 | M33: =SUBTOTAL(9,M34:M35) -> 58183538 | N33: =SUBTOTAL(9,N34:N35) -> 0.0238 | ... U33: =SUBTOTAL(9,U34:U35) -> 54085380 | V33: =W33/$W$10 -> 0.041196856 | W33: =SUBTOTAL(9,W34:W35) -> 76550406 | X33: =SUBTOTAL(9,X34:X35) -> 0.087048694 | Y33: =SUBTOTAL(9,Y34:Y35) -> 220871764 | Z33: =AA33/$AA$10 -> 0.061589954 | AA33: =SUBTOTAL(9,AA34:AA35) -> 151651871 | AB33: =SUBTOTAL(9,AB34:AB35) -> 0 | AC33: =SUBTOTAL(9,AC34:AC35) -> 96263350 | AD33: =E33/$E$9 -> 0.041007938
A34: 6421.2 | B34: 334.5 | C34: Lương/Thưởng cho bộ phận HCNS | D34: =E34/$E$10 -> 0.017528456 | E34: =G34+I34+K34+M34+O34+Q34+S34+U34+W34+Y34+AA34+AC34 -> 392917120 | F34: 0.0154 | G34: 34465550 | H34: 0.0206 | I34: 33377875 | J34: 0.0195 | K34: 34465550 | L34: 0.0189 | M34: 34529000 | N34: 0.018 | O34: 34529000 | P34: 0.0147 | Q34: 34529000 | R34: 0.0144 | S34: 27960594 | T34: =U34/$U$9 -> 0.01307434 | U34: 24685380 | V34: =W34/$W$10 -> 0.017238764 | W34: 32032406 | X34: =Y34/$Y$10 -> 0.012870218 | Y34: 32656064 | Z34: =AA34/$AA$10 -> 0.014150834 | AA34: 34843351 | AC34: 34843350 | AD34: =E34/$E$9 -> 0.016571549
B35: 6422.5 | C35: Các chi phí hoạt động nội bộ | D35: =E35/$E$10 -> 0.025847443 | E35: =G35+I35+K35+M35+O35+Q35+S35+U35+W35+Y35+AA35+AC35 -> 579395174 | F35: 0.0038 | G35: 8416256 | H35: 0.0072 | I35: 11599800 | J35: 0.0127 | K35: 22431200 | L35: 0.0129 | M35: 23654538 | N35: 0.0058 | O35: 11166000 | P35: 0.0032 | Q35: 7500000 | R35: 0.028 | S35: 54265160 | T35: =U35/$U$9 -> 0.015571387 | U35: 29400000 | V35: =W35/$W$10 -> 0.023958091 | W35: 44518000 | X35: =Y35/$Y$10 -> 0.074178476 | Y35: 188215700 | Z35: =AA35/$AA$10 -> 0.04743912 | AA35: 116808520 | AC35: =16520000+24900000+20000000 -> 61420000 | AD35: =E35/$E$9 -> 0.024436389
B36: Kế toán/Tài Chính | D36: =E36/$E$10 -> 0.019442578 | E36: =G36+I36+K36+M36+O36+Q36+S36+U36+W36+Y36+AA36+AC36 -> 435824000 | F36: 0.02 | G36: =SUBTOTAL(9,G37:G38) -> 44604500 | H36: =SUBTOTAL(9,H37:H38) -> 0.0209 | I36: =SUBTOTAL(9,I37:I38) -> 33864500 | J36: =SUBTOTAL(9,J37:J38) -> 0.0187 | K36: =SUBTOTAL(9,K37:K38) -> 33029000 | L36: =SUBTOTAL(9,L37:L38) -> 0.0182 | M36: =SUBTOTAL(9,M37:M38) -> 33409000 | N36: =SUBTOTAL(9,N37:N38) -> 0.0172 | ... U36: =SUBTOTAL(9,U37:U38) -> 37466000 | V36: =W36/$W$10 -> 0.020162942 | W36: =SUBTOTAL(9,W37:W38) -> 37466000 | X36: =SUBTOTAL(9,X37:X38) -> 0.014765882 | Y36: =SUBTOTAL(9,Y37:Y38) -> 37466000 | Z36: =AA36/$AA$10 -> 0.015215963 | AA36: =SUBTOTAL(9,AA37:AA38) -> 37466000 | AB36: =SUBTOTAL(9,AB37:AB38) -> 0 | AC36: =SUBTOTAL(9,AC37:AC38) -> 37466000 | AD36: =E36/$E$9 -> 0.018381176
A37: 6422.6 | B37: 334.3 | C37: Lương bộ phận kế toán | D37: =E37/$E$10 -> 0.018919736 | E37: =G37+I37+K37+M37+O37+Q37+S37+U37+W37+Y37+AA37+AC37 -> 424104000 | F37: 0.0149 | G37: 33264500 | H37: 0.0209 | I37: 33864500 | J37: 0.0187 | K37: 33029000 | L37: 0.018 | M37: 33029000 | N37: 0.0172 | O37: 33029000 | P37: 0.0141 | Q37: 33029000 | R37: 0.0194 | S37: 37529000 | T37: =U37/$U$9 -> 0.019843455 | U37: 37466000 | V37: =W37/$W$10 -> 0.020162942 | W37: 37466000 | X37: =Y37/$Y$10 -> 0.014765882 | Y37: 37466000 | Z37: =AA37/$AA$10 -> 0.015215963 | AA37: 37466000 | AC37: 37466000 | AD37: =E37/$E$9 -> 0.017886877
B38: 6422.7 | C38: Chi phí xử lý thuế, các vấn đề về kế toán (nếu có) | D38: =E38/$E$10 -> 0.00052284182 | E38: =G38+I38+K38+M38+O38+Q38+S38+U38+W38+Y38+AA38+AC38 -> 11720000 | F38: 0.0051 | G38: 11340000 | H38: 0 | I38: 0 | J38: 0 | K38: 0 | L38: 0.0002 | M38: 380000 | N38: 0 | O38: 0 | P38: 0 | Q38: 0 | R38: 0 | S38: 0 | T38: =U38/$U$9 -> 0 | U38: 0 | V38: =W38/$W$10 -> 0 | X38: =Y38/$Y$10 -> 0 | Z38: =AA38/$AA$10 -> 0 | AD38: =E38/$E$9 -> 0.00049429904
B39: Sales | D39: =E39/$E$10 -> 0.071045877 | E39: =G39+I39+K39+M39+O39+Q39+S39+U39+W39+Y39+AA39+AC39 -> 1592561346 | F39: 0.0247 | G39: =SUBTOTAL(9,G40:G45) -> 55247392 | H39: =SUBTOTAL(9,H40:H45) -> 0.045 | I39: =SUBTOTAL(9,I40:I45) -> 72806980 | J39: =SUBTOTAL(9,J40:J45) -> 0.0749 | K39: =SUBTOTAL(9,K40:K45) -> 132411151 | L39: =SUBTOTAL(9,L40:L45) -> 0.0656 | M39: =SUBTOTAL(9,M40:M45) -> 120029622 | N39: =SUBTOTAL(9,N40:N45) -> 0.07 | ... U39: =SUBTOTAL(9,U40:U45) -> 178795376 | V39: =W39/$W$10 -> 0.10762058 | W39: =SUBTOTAL(9,W40:W45) -> 199976404 | X39: =SUBTOTAL(9,X40:X45) -> 0.075991742 | Y39: =SUBTOTAL(9,Y40:Y45) -> 192816565 | Z39: =AA39/$AA$10 -> 0.063668349 | AA39: =SUBTOTAL(9,AA40:AA45) -> 156769467 | AB39: =SUBTOTAL(9,AB40:AB45) -> 0 | AC39: =SUBTOTAL(9,AC40:AC45) -> 150480593 | AD39: =E39/$E$9 -> 0.067167367 | AE39: =8/100*E10 -> 1793276582 | AF39: =AE39-E39-E46 -> -181542357
A40: 6421.3 | B40: 334.6 | C40: Lương NV Sales | D40: =E40/$E$10 -> 0.033827591 | E40: =G40+I40+K40+M40+O40+Q40+S40+U40+W40+Y40+AA40+AC40 -> 758277843 | F40: 0.0108 | G40: 24115000 | H40: 0.015 | I40: 24256000 | J40: 0.0228 | K40: 40243750 | L40: 0.0275 | M40: 50244750 | N40: 0.0271 | O40: 52159046 | P40: 0.024 | Q40: 56334044 | R40: 0.0356 | S40: 69056775 | T40: =U40/$U$9 -> 0.039998679 | U40: =51405643+24115000 -> 75520643 | V40: =W40/$W$10 -> 0.051317993 | W40: =58867113 +24115000+12375000 -> 95357113 | X40: =Y40/$Y$10 -> 0.038117738 | Y40: =60227500+36490000 -> 96717500 | Z40: =AA40/$AA$10 -> 0.034904424 | AA40: =61829556+24115000 -> 85944556 | AC40: 88328666 | AD40: =E40/$E$9 -> 0.031980888
A41: 6421.4 | C41: Công cụ phục vụ Sales | D41: =E41/$E$10 -> 0.0041686025 | E41: =G41+I41+K41+M41+O41+Q41+S41+U41+W41+Y41+AA41+AC41 -> 93443216 | F41: 0 | G41: 0 | H41: 0.0021 | I41: 3345630 | J41: 0.0056 | K41: 9918031 | L41: 0.015 | M41: 27540313 | N41: 0.0032 | O41: 6208036 | P41: 0.0046 | Q41: 10765578 | R41: 0.0047 | S41: 9148421 | T41: =U41/$U$9 -> 0.0033912463 | U41: 6402939 | V41: =W41/$W$10 -> 0.0021048274 | W41: 3911109 | X41: =Y41/$Y$10 -> 0.0033257396 | Y41: 8438518 | Z41: =AA41/$AA$10 -> 0.0030307817 | AA41: 7462641 | AC41: 302000 | AD41: =E41/$E$9 -> 0.0039410317
A42: 6421.5 | C42: Tiếp khách | D42: =E42/$E$10 -> 0.00083020528 | E42: =G42+I42+K42+M42+O42+Q42+S42+U42+W42+Y42+AA42+AC42 -> 18609846 | F42: 0.0035 | G42: 7832392 | H42: 0.0003 | I42: 515500 | J42: 0.0011 | K42: 1969378 | L42: 0.0001 | M42: 108270 | N42: 0 | O42: 0 | P42: 0.0015 | Q42: 3544381 | R42: 0 | S42: 60000 | T42: =U42/$U$9 -> 0.001286508 | U42: 2429028 | V42: =W42/$W$10 -> 0 | X42: =Y42/$Y$10 -> 0 | Z42: =AA42/$AA$10 -> 0.00087353783 | AA42: 2150897 | AD42: =E42/$E$9 -> 0.00078488301
...

Sheet Project
A1: STT | B1: CÔNG TY | C1: DỰ ÁN | E1: Type | F1: Type | I1: T01 | Q1: T02 | Y1: TỔNG NĂM 2025 | AB1: TỔNG DỰ ÁN | AD1: DỰ ÁN | AK1: T05 | AP1: T06 | AU1: T07 | AZ1: T08 | BE1: T09 | BJ1: T10 | BO1: T11 | BT1: T12 | BY1: TỔNG DỰ ÁN | CA1: DỰ ÁN
F2: Type | H2: DƯ ĐẦU KỲ | I2: Thu | J2: Tạm ứng | K2: Tổng THU | L2: Vendor | M2: Inhouse | N2: CHI KHÔNG THU ĐƯỢC | O2: Tổng CHI | P2: LỖ/LÃI | Q2: Thu | R2: Tạm ứng | S2: Tổng THU | T2: Vendor | U2: Inhouse | V2: CHI KHÔNG THU ĐƯỢC | W2: Tổng CHI | X2: LỖ/LÃI | Y2: THU | Z2: CHI | AA2: LỖ/LÃI | AC2: % | AG2: Tạm ứng | AH2: CHI | AI2: % | AJ2: LỖ/LÃI | AK2: THU | AL2: Tạm ứng | AM2: CHI | AN2: % | AO2: LỖ/LÃI | AP2: THU | AQ2: Tạm ứng | AR2: CHI | AS2: % | AT2: LỖ/LÃI | AU2: THU | AV2: Tạm ứng | AW2: CHI | AX2: % | AY2: LỖ/LÃI | AZ2: THU | BA2: Tạm ứng | BB2: CHI | BC2: % | BD2: LỖ/LÃI | BE2: THU | BF2: Tạm ứng | BG2: CHI | BH2: % | BI2: LỖ/LÃI | BJ2: THU | BK2: Tạm ứng | BL2: CHI | BM2: % | BN2: LỖ/LÃI | BO2: THU | BP2: Tạm ứng | BQ2: CHI | BR2: % | BS2: LỖ/LÃI | BT2: THU | BU2: Tạm ứng | BV2: CHI | BW2: % | BX2: LỖ/LÃI | BZ2: %
A3: 1 | B3: ELMODINO | C3: eShotLink | D3: Completed | E3: T&M | F3: Non-blockchain | G3: =B3&"_"&C3 -> ELMODINO_eShotLink | L3: 0 | O3: 0 | P3: 0 | Q3: 0 | V3: 0 | Z3: 0 | AA3: 0 | AB3: =AA3+H3 -> 0 | AD3: =C3 -> eShotLink | AF3: =Y3/$Y$130 -> #DIV/0! | BY3: =G3+J3 -> #VALUE! | CA3: eShotLink
A4: =IF(C4="","",A3+1) -> 2 | B4: QSOFT | C4: Bluefire AI | D4: On-going | E4: T&M | F4: Non-blockchain | G4: =B4&"_"&C4 -> QSOFT_Bluefire AI | J4: 36467500 | L4: 36467500 | N4: 18937500 | P4: 18937500 | Q4: 17530000 | R4: 0.4807 | T4: 27147149 | V4: 27147149 | X4: 17034000 | Z4: 17034000 | AA4: 10113149 | AB4: =AA4+H4 -> 10113149 | AD4: =C4 -> Bluefire AI | AF4: =Y4/$Y$130 -> #DIV/0! | BY4: =G4+J4 -> #VALUE! | CA4: Bluefire AI
A5: =IF(C5="","",A4+1) -> 3 | C5: ITOP Sensorflow | D5: Completed | E5: T&M | F5: Non-blockchain | G5: =B5&"_"&C5 -> _ITOP Sensorflow | L5: 0 | O5: 0 | P5: 0 | Q5: 0 | V5: 0 | Z5: 0 | AA5: 0 | AB5: =AA5+H5 -> 0 | AD5: =C5 -> ITOP Sensorflow | AF5: =Y5/$Y$130 -> #DIV/0! | BY5: =G5+J5 -> #VALUE! | CA5: ITOP Sensorflow
A6: 2 | C6: ITOP Intribe | D6: Completed | E6: T&M | F6: Non-blockchain | G6: =B6&"_"&C6 -> _ITOP Intribe | L6: 0 | O6: 0 | P6: 0 | Q6: 0 | V6: 0 | Z6: 0 | AA6: 0 | AB6: =AA6+H6 -> 0 | AD6: =C6 -> ITOP Intribe | AF6: =Y6/$Y$130 -> #DIV/0! | BY6: =G6+J6 -> #VALUE! | CA6: ITOP Intribe
A7: =IF(C7="","",A6+1) -> 3 | C7: ITOP Arcanum | D7: Completed | E7: T&M | F7: Non-blockchain | G7: =B7&"_"&C7 -> _ITOP Arcanum | L7: 0 | O7: 0 | P7: 0 | Q7: 0 | V7: 0 | Z7: 0 | AA7: 0 | AB7: =AA7+H7 -> 0 | AD7: =C7 -> ITOP Arcanum | BY7: =G7+J7 -> #VALUE! | CA7: ITOP Arcanum
A8: =IF(C8="","",A7+1) -> 4 | B8: QSOFT | C8: Chocolate | D8: On-going | E8: T&M | F8: Non-blockchain | G8: =B8&"_"&C8 -> QSOFT_Chocolate | I8: 147641943 | J8: 351071139 | L8: 498713082 | M8: 85153193 | N8: 243635500 | P8: 328788693 | Q8: 169924389 | R8: 0.3407 | S8: 115141365 | T8: 263982649 | V8: 379124014 | W8: 82433201 | X8: 182199348 | Z8: 264632549 | AA8: 114491465 | AB8: =AA8+H8 -> 114491465 | AD8: =C8 -> Chocolate | AF8: =Y8/$Y$130 -> #DIV/0! | BY8: =G8+J8 -> #VALUE! | CA8: Chocolate
A9: 3 | B9: VITEX | C9: Vitex | D9: On-going | E9: T&M | F9: Non-blockchain | G9: =B9&"_"&C9 -> VITEX_Vitex | J9: 35000000 | L9: 35000000 | N9: 22000000 | P9: 22000000 | Q9: 13000000 | R9: 0.3714 | T9: 25870000 | V9: 25870000 | X9: 17000000 | Z9: 17000000 | AA9: 8870000 | AB9: =AA9+H9 -> 8870000 | AD9: =C9 -> Vitex | AF9: =Y9/$Y$130 -> #DIV/0! | BY9: =G9+J9 -> #VALUE! | CA9: Vitex
A10: =IF(C10="","",A9+1) -> 4 | B10: VITEX | C10: MGH | D10: Completed | E10: T&M | F10: Blockchain | G10: =B10&"_"&C10 -> VITEX_MGH | I10: 31564000 | L10: 31564000 | M10: 0 | P10: 0 | Q10: 31564000 | R10: 1 | S10: 0 | V10: 0 | Z10: 0 | AA10: 0 | AB10: =AA10+H10 -> 0 | AD10: =C10 -> MGH | BY10: =G10+J10 -> #VALUE! | CA10: MGH
A11: =IF(C11="","",A10+1) -> 5 | B11: VITEX | C11: Xlinq | D11: On-going | E11: T&M | F11: Non-blockchain | G11: =B11&"_"&C11 -> VITEX_Xlinq | J11: 75000000 | L11: 75000000 | N11: 55556500 | P11: 55556500 | Q11: 19443500 | R11: 0.2592 | T11: 55434000 | V11: 55434000 | X11: 41063500 | Z11: 41063500 | AA11: 14370500 | AB11: =AA11+H11 -> 14370500 | AD11: =C11 -> Xlinq | BY11: =G11+J11 -> #VALUE! | CA11: Xlinq
A12: 4 | B12: MintedGEM | C12: MintedGEM | D12: On-going | E12: Fixedprice | F12: Blockchain | G12: =B12&"_"&C12 -> MintedGEM_MintedGEM | L12: 0 | O12: 1467909 | P12: 1467909 | Q12: -1467909 | V12: 0 | Z12: 0 | AA12: 0 | AB12: =AA12+H12 -> 0 | AD12: =C12 -> MintedGEM | AF12: =Y12/$Y$130 -> #DIV/0! | BY12: =G12+J12 -> #VALUE! | CA12: MintedGEM
A13: =IF(C13="","",A12+1) -> 5 | B13: ICE | C13: M&A&Stock Mobile app | D13: Completed | E13: Fixedprice | F13: Non-blockchain | G13: =B13&"_"&C13 -> ICE_M&A&Stock Mobile app | I13: 36000000 | L13: 36000000 | M13: 31405864 | P13: 31405864 | Q13: 4594136 | R13: 0.1276 | V13: 0 | Z13: 0 | AA13: 0 | AB13: =AA13+H13 -> 0 | AD13: =C13 -> M&A&Stock Mobile app | AF13: =Y13/$Y$130 -> #DIV/0! | BY13: =G13+J13 -> #VALUE! | CA13: M&A&Stock Mobile app
A14: =IF(C14="","",A13+1) -> 6 | B14: C2E | C14: C2E | D14: Completed | E14: Fixedprice | F14: Blockchain | G14: =B14&"_"&C14 -> C2E_C2E | L14: 0 | O14: 0 | P14: 0 | Q14: 0 | V14: 0 | Z14: 0 | AA14: 0 | AB14: =AA14+H14 -> 0 | AD14: =C14 -> C2E | AF14: =Y14/$Y$130 -> #DIV/0! | BY14: =G14+J14 -> #VALUE! | CA14: C2E
A15: 5 | B15: Inhouse | C15: Blockchain nội bộ | D15: On-going | F15: Blockchain | G15: =B15&"_"&C15 -> Inhouse_Blockchain nội bộ | L15: 0 | O15: 9613549 | P15: 9613549 | Q15: -9613549 | V15: 0 | Z15: 0 | AA15: 0 | AB15: =AA15+H15 -> 0 | AD15: =C15 -> Blockchain nội bộ | AF15: =Y15/$Y$130 -> #DIV/0! | BY15: =G15+J15 -> #VALUE! | CA15: Blockchain nội bộ
A16: =IF(C16="","",A15+1) -> 6 | C16: Internal NFT WhiteLabel | D16: On-going | F16: Blockchain | G16: =B16&"_"&C16 -> _Internal NFT WhiteLabel | L16: 0 | O16: 0 | P16: 0 | Q16: 0 | V16: 0 | Z16: 0 | AA16: 0 | AB16: =AA16+H16 -> 0 | AD16: =C16 -> Internal NFT WhiteLabel | BY16: =G16+J16 -> #VALUE!
A17: =IF(C17="","",A16+1) -> 7 | C17: ConnectX | D17: On-going | F17: Blockchain | G17: =B17&"_"&C17 -> _ConnectX | L17: 0 | O17: 5393093 | P17: 5393093 | Q17: -5393093 | V17: 0 | Z17: 0 | AA17: 0 | AB17: =AA17+H17 -> 0 | AD17: =C17 -> ConnectX | BY17: =G17+J17 -> #VALUE!
A18: 6 | C18: Sales support | D18: On-going | F18: Non-blockchain | G18: =B18&"_"&C18 -> _Sales support | L18: 0 | O18: 26229818 | P18: 26229818 | Q18: -26229818 | V18: 0 | Z18: 0 | AA18: 0 | AB18: =AA18+H18 -> 0 | AD18: =C18 -> Sales support | BY18: =G18+J18 -> #VALUE!
A19: =IF(C19="","",A18+1) -> 7 | B19: Tiberiu | C19: BRC | D19: Completed | E19: T&M | F19: Non-blockchain | G19: =B19&"_"&C19 -> Tiberiu_BRC | L19: 0 | O19: 0 | P19: 0 | Q19: 0 | V19: 0 | Z19: 0 | AA19: 0 | AB19: =AA19+H19 -> 0 | AD19: =C19 -> BRC | BY19: =G19+J19 -> #VALUE! | CA19: BRC
A20: =IF(C20="","",A19+1) -> 8 | B20: Adam | C20: Crowd Funding | D20: Completed | E20: Fixedprice | F20: Non-blockchain | G20: =B20&"_"&C20 -> Adam_Crowd Funding | L20: 0 | O20: 0 | P20: 0 | Q20: 0 | V20: 0 | Z20: 0 | AA20: 0 | AB20: =AA20+H20 -> 0 | AD20: =C20 -> Crowd Funding | BY20: =G20+J20 -> #VALUE! | CA20: Crowd Funding
A21: 7 | B21: DTS | C21: DTS_01 | D21: Completed | E21: T&M | F21: Non-blockchain | G21: =B21&"_"&C21 -> DTS_DTS_01 | L21: 0 | O21: 0 | P21: 0 | Q21: 0 | V21: 0 | Z21: 0 | AA21: 0 | AB21: =AA21+H21 -> 0 | AD21: =C21 -> DTS_01 | BY21: =G21+J21 -> #VALUE! | CA21: DTS
A22: =IF(C22="","",A21+1) -> 8 | C22: DTS_02 | D22: Completed | E22: T&M | F22: Non-blockchain | G22: =B22&"_"&C22 -> _DTS_02 | L22: 0 | O22: 0 | P22: 0 | Q22: 0 | V22: 0 | Z22: 0 | AA22: 0 | AB22: =AA22+H22 -> 0 | AD22: =C22 -> DTS_02 | BY22: =G22+J22 -> #VALUE!
A23: =IF(C23="","",A22+1) -> 9 | C23: DTS_03 | D23: Completed | E23: T&M | F23: Non-blockchain | G23: =B23&"_"&C23 -> _DTS_03 | L23: 0 | O23: 0 | P23: 0 | Q23: 0 | V23: 0 | Z23: 0 | AA23: 0 | AB23: =AA23+H23 -> 0 | AD23: =C23 -> DTS_03
A24: 8 | B24: MOR | C24: MOR | D24: Completed | E24: T&M | F24: Non-blockchain | G24: =B24&"_"&C24 -> MOR_MOR | L24: 0 | O24: 0 | P24: 0 | Q24: 0 | V24: 0 | Z24: 0 | AA24: 0 | AB24: =AA24+H24 -> 0 | AD24: =C24 -> MOR | BY24: =G24+J24 -> #VALUE! | CA24: MOR
A25: =IF(C25="","",A24+1) -> 9 | B25: ICETEA | C25: ICETEA_Clevai onsite | D25: Completed | E25: T&M | F25: Non-blockchain | G25: =B25&"_"&C25 -> ICETEA_ICETEA_Clevai onsite | L25: 0 | O25: 0 | P25: 0 | Q25: 0 | V25: 0 | Z25: 0 | AA25: 0 | AB25: =AA25+H25 -> 0 | AD25: =C25 -> ICETEA_Clevai onsite | BY25: =G25+J25 -> #VALUE! | CA25: ICETEA_Clevai onsite
A26: =IF(C26="","",A25+1) -> 10 | C26: ICETEA_NCB onsite | D26: Completed | E26: T&M | F26: Non-blockchain | G26: =B26&"_"&C26 -> _ICETEA_NCB onsite | L26: 0 | O26: 0 | P26: 0 | Q26: 0 | V26: 0 | Z26: 0 | AA26: 0 | AB26: =AA26+H26 -> 0 | AD26: =C26 -> ICETEA_NCB onsite | BY26: =G26+J26 -> #VALUE! | CA26: ICETEA_NCB onsite
A27: 9 | B27: Sen Việt | C27: Sen Việt | D27: Completed | E27: Fixedprice | F27: Non-blockchain | G27: =B27&"_"&C27 -> Sen Việt_Sen Việt | L27: 0 | O27: 2535370 | P27: 2535370 | Q27: -2535370 | V27: 0 | Z27: 0 | AA27: 0 | AB27: =AA27+H27 -> 0 | AD27: =C27 -> Sen Việt | BY27: =G27+J27 -> #VALUE! | CA27: Sen Việt
A28: =IF(C28="","",A27+1) -> 10 | B28: Web3 | C28: Web3Research | D28: On-going | E28: T&M | F28: Blockchain | G28: =B28&"_"&C28 -> Web3_Web3Research | J28: 60406511 | L28: 60406511 | N28: 40090909 | P28: 40090909 | Q28: 20315602 | R28: 0.3363 | T28: 62798314 | V28: 62798314 | X28: 31043478 | Z28: 31043478 | AA28: 31754836 | AB28: =AA28+H28 -> 31754836 | AD28: =C28 -> Web3Research | BY28: =G28+J28 -> #VALUE! | CA28: Web3
A29: =IF(C29="","",A28+1) -> 11 | B29: Ái Việt | C29: Ái Việt | D29: Completed | E29: Fixedprice | F29: Non-blockchain | G29: =B29&"_"&C29 -> Ái Việt_Ái Việt | L29: 0 | O29: 0 | P29: 0 | Q29: 0 | V29: 0 | Z29: 0 | AA29: 0 | AB29: =AA29+H29 -> 0 | AD29: =C29 -> Ái Việt | BY29: =G29+J29 -> #VALUE! | CA29: Ái Việt
A30: 10 | B30: GTS | C30: GTS | D30: Completed | E30: T&M | F30: Non-blockchain | G30: =B30&"_"&C30 -> GTS_GTS | L30: 0 | O30: 0 | P30: 0 | Q30: 0 | V30: 0 | Z30: 0 | AA30: 0 | AB30: =AA30+H30 -> 0 | AD30: =C30 -> GTS | BY30: =G30+J30 -> #VALUE! | CA30: GTS
A31: =IF(C31="","",A30+1) -> 11 | B31: Thảo Nguyên | C31: Thảo Nguyên Shop_01 | D31: Completed | E31: Fixedprice | F31: Non-blockchain | G31: =B31&"_"&C31 -> Thảo Nguyên_Thảo Nguyên Shop_01 | L31: 0 | O31: 0 | P31: 0 | Q31: 0 | V31: 0 | Z31: 0 | AA31: 0 | AB31: =AA31+H31 -> 0 | AD31: =C31 -> Thảo Nguyên Shop_01 | BY31: =G31+J31 -> #VALUE! | CA31: Thảo Nguyên Shop_01
A32: =IF(C32="","",A31+1) -> 12 | C32: Thảo Nguyên Shop_02 | D32: Completed | E32: Fixedprice | F32: Non-blockchain | G32: =B32&"_"&C32 -> _Thảo Nguyên Shop_02 | L32: 0 | O32: 0 | P32: 0 | Q32: 0 | V32: 0 | Z32: 0 | AA32: 0 | AB32: =AA32+H32 -> 0 | AD32: =C32 -> Thảo Nguyên Shop_02 | BY32: =G32+J32 -> #VALUE! | CA32: Thảo Nguyên Shop_02
A33: 11 | C33: Thảo Nguyên Shop_03 | D33: Completed | E33: Fixedprice | F33: Non-blockchain | G33: =B33&"_"&C33 -> _Thảo Nguyên Shop_03 | L33: 0 | O33: 0 | P33: 0 | Q33: 0 | V33: 0 | Z33: 0 | AA33: 0 | AB33: =AA33+H33 -> 0 | AD33: =C33 -> Thảo Nguyên Shop_03 | BY33: =G33+J33 -> #VALUE!
A34: =IF(C34="","",A33+1) -> 12 | B34: MHS | C34: MHS | D34: Completed | E34: T&M | F34: Non-blockchain | G34: =B34&"_"&C34 -> MHS_MHS | L34: 0 | O34: 0 | P34: 0 | Q34: 0 | V34: 0 | Z34: 0 | AA34: 0 | AB34: =AA34+H34 -> 0 | AD34: =C34 -> MHS | BY34: =G34+J34 -> #VALUE! | CA34: MHS
A35: =IF(C35="","",A34+1) -> 13 | B35: SYSYEMEXE | C35: FLUZO | D35: Completed | E35: T&M | F35: Non-blockchain | G35: =B35&"_"&C35 -> SYSYEMEXE_FLUZO | L35: 0 | O35: 0 | P35: 0 | Q35: 0 | V35: 0 | Z35: 0 | AA35: 0 | AB35: =AA35+H35 -> 0 | AD35: =C35 -> FLUZO | BY35: =G35+J35 -> #VALUE!
A36: 12 | B36: ZINZA | C36: Zinza | D36: Completed | E36: T&M | F36: Blockchain | G36: =B36&"_"&C36 -> ZINZA_Zinza | L36: 0 | O36: 0 | P36: 0 | Q36: 0 | V36: 0 | Z36: 0 | AA36: 0 | AB36: =AA36+H36 -> 0 | AD36: =C36 -> Zinza | BY36: =G36+J36 -> #VALUE!
A37: =IF(C37="","",A36+1) -> 13 | B37: NDH | C37: Casoni | D37: Completed | E37: T&M | F37: Blockchain | G37: =B37&"_"&C37 -> NDH_Casoni | L37: 0 | O37: 0 | P37: 0 | Q37: 0 | V37: 0 | Z37: 0 | AA37: 0 | AB37: =AA37+H37 -> 0 | AD37: =C37 -> Casoni | BY37: =G37+J37 -> #VALUE! | CA37: 30240274
A38: =IF(C38="","",A37+1) -> 14 | B38: Hitek | C38: Hitek_Seegman | D38: Completed | E38: Fixedprice | F38: Non-blockchain | G38: =B38&"_"&C38 -> Hitek_Hitek_Seegman | L38: 0 | O38: 0 | P38: 0 | Q38: 0 | V38: 0 | Z38: 0 | AA38: 0 | AB38: =AA38+H38 -> 0 | AD38: =C38 -> Hitek_Seegman | BY38: =G38+J38 -> #VALUE!
A39: 13 | C39: Hitek_Allone2 | D39: Completed | E39: Fixedprice | F39: Non-blockchain | G39: =B39&"_"&C39 -> _Hitek_Allone2 | L39: 0 | O39: 0 | P39: 0 | Q39: 0 | V39: 0 | Z39: 0 | AA39: 0 | AB39: =AA39+H39 -> 0 | AD39: =C39 -> Hitek_Allone2 | BY39: =G39+J39 -> #VALUE!
A40: =IF(C40="","",A39+1) -> 14 | C40: Hitek_240 APIs | D40: Completed | E40: Fixedprice | F40: Non-blockchain | G40: =B40&"_"&C40 -> _Hitek_240 APIs | L40: 0 | O40: 0 | P40: 0 | Q40: 0 | V40: 0 | Z40: 0 | AA40: 0 | AB40: =AA40+H40 -> 0 | AD40: =C40 -> Hitek_240 APIs | BY40: =G40+J40 -> #VALUE!
...
